Internal Server Error: /Sentiment_Analyzer
Traceback (most recent call last):
  File "/home/rducky/virtualenvs/calvintech/lib/python3.8/site-packages/nltk/corpus/util.py", line 83, in __load
    root = nltk.data.find("{}/{}".format(self.subdir, zip_name))
  File "/home/rducky/virtualenvs/calvintech/lib/python3.8/site-packages/nltk/data.py", line 585, in find
    raise LookupError(resource_not_found)
LookupError: 
**********************************************************************
  Resource [93mwordnet[0m not found.
  Please use the NLTK Downloader to obtain the resource:

  [31m>>> import nltk
  >>> nltk.download('wordnet')
  [0m
  For more information see: https://www.nltk.org/data.html

  Attempted to load [93mcorpora/wordnet.zip/wordnet/[0m

  Searched in:
    - '/home/rducky/nltk_data'
    - '/home/rducky/virtualenvs/calvintech/nltk_data'
    - '/home/rducky/virtualenvs/calvintech/share/nltk_data'
    - '/home/rducky/virtualenvs/calvintech/lib/nltk_data'
    - '/usr/share/nltk_data'
    - '/usr/local/share/nltk_data'
    - '/usr/lib/nltk_data'
    - '/usr/local/lib/nltk_data'
**********************************************************************


During handling of the above exception, another exception occurred:

Traceback (most recent call last):
  File "/home/rducky/virtualenvs/calvintech/lib/python3.8/site-packages/django/core/handlers/exception.py", line 34, in inner
    response = get_response(request)
  File "/home/rducky/virtualenvs/calvintech/lib/python3.8/site-packages/django/core/handlers/base.py", line 115, in _get_response
    response = self.process_exception_by_middleware(e, request)
  File "/home/rducky/virtualenvs/calvintech/lib/python3.8/site-packages/django/core/handlers/base.py", line 113, in _get_response
    response = wrapped_callback(request, *callback_args, **callback_kwargs)
  File "/var/www/calvin-tech/calvinTech/views.py", line 28, in Sentiment_Analyzer
    sentiment = getSentiment(data)
  File "/var/www/calvin-tech/calvinTech/getSentiment.py", line 56, in getSentiment
    corpus = buildCorpus(df)
  File "/var/www/calvin-tech/calvinTech/getSentiment.py", line 42, in buildCorpus
    s[i] = lemmatizer.lemmatize(s[i])
  File "/home/rducky/virtualenvs/calvintech/lib/python3.8/site-packages/nltk/stem/wordnet.py", line 38, in lemmatize
    lemmas = wordnet._morphy(word, pos)
  File "/home/rducky/virtualenvs/calvintech/lib/python3.8/site-packages/nltk/corpus/util.py", line 120, in __getattr__
    self.__load()
  File "/home/rducky/virtualenvs/calvintech/lib/python3.8/site-packages/nltk/corpus/util.py", line 85, in __load
    raise e
  File "/home/rducky/virtualenvs/calvintech/lib/python3.8/site-packages/nltk/corpus/util.py", line 80, in __load
    root = nltk.data.find("{}/{}".format(self.subdir, self.__name))
  File "/home/rducky/virtualenvs/calvintech/lib/python3.8/site-packages/nltk/data.py", line 585, in find
    raise LookupError(resource_not_found)
LookupError: 
**********************************************************************
  Resource [93mwordnet[0m not found.
  Please use the NLTK Downloader to obtain the resource:

  [31m>>> import nltk
  >>> nltk.download('wordnet')
  [0m
  For more information see: https://www.nltk.org/data.html

  Attempted to load [93mcorpora/wordnet[0m

  Searched in:
    - '/home/rducky/nltk_data'
    - '/home/rducky/virtualenvs/calvintech/nltk_data'
    - '/home/rducky/virtualenvs/calvintech/share/nltk_data'
    - '/home/rducky/virtualenvs/calvintech/lib/nltk_data'
    - '/usr/share/nltk_data'
    - '/usr/local/share/nltk_data'
    - '/usr/lib/nltk_data'
    - '/usr/local/lib/nltk_data'
**********************************************************************

Internal Server Error: /Sentiment_Analyzer
Traceback (most recent call last):
  File "/home/rducky/anaconda3/envs/django-dev/lib/python3.8/site-packages/django/core/handlers/exception.py", line 34, in inner
    response = get_response(request)
  File "/home/rducky/anaconda3/envs/django-dev/lib/python3.8/site-packages/django/core/handlers/base.py", line 115, in _get_response
    response = self.process_exception_by_middleware(e, request)
  File "/home/rducky/anaconda3/envs/django-dev/lib/python3.8/site-packages/django/core/handlers/base.py", line 113, in _get_response
    response = wrapped_callback(request, *callback_args, **callback_kwargs)
  File "/home/rducky/Web-Dev/mainSite/calvinTech/views.py", line 28, in Sentiment_Analyzer
    sentiment = getSentiment(data)
  File "/home/rducky/Web-Dev/mainSite/calvinTech/getSentiment.py", line 61, in getSentiment
    df1['input'] = corpus
NameError: name 'corpus' is not defined
"POST /Sentiment_Analyzer HTTP/1.1" 500 87003
Internal Server Error: /Sentiment_Analyzer
Traceback (most recent call last):
  File "/home/rducky/anaconda3/envs/django-dev/lib/python3.8/site-packages/django/core/handlers/exception.py", line 34, in inner
    response = get_response(request)
  File "/home/rducky/anaconda3/envs/django-dev/lib/python3.8/site-packages/django/core/handlers/base.py", line 115, in _get_response
    response = self.process_exception_by_middleware(e, request)
  File "/home/rducky/anaconda3/envs/django-dev/lib/python3.8/site-packages/django/core/handlers/base.py", line 113, in _get_response
    response = wrapped_callback(request, *callback_args, **callback_kwargs)
  File "/home/rducky/Web-Dev/mainSite/calvinTech/views.py", line 28, in Sentiment_Analyzer
    sentiment = getSentiment(data)
  File "/home/rducky/Web-Dev/mainSite/calvinTech/getSentiment.py", line 61, in getSentiment
    df1['input'] = corpus
NameError: name 'corpus' is not defined
"POST /Sentiment_Analyzer HTTP/1.1" 500 87003
